Autotested Results for N/A submitted by 
Generated at N/A

Summary of Results: 32 out of 37 tests successfully passed
--

Tests for args_tests.ArgumentsTest (5/5 passed)
--

1) args_tests.ArgumentsTest.test_createfile_extraargs                                 .. ok!
2) args_tests.ArgumentsTest.test_createfile_noarg                                     .. ok!
3) args_tests.ArgumentsTest.test_deletefile_noarg                                     .. ok!
4) args_tests.ArgumentsTest.test_readfile_missingarg                                  .. ok!
5) args_tests.ArgumentsTest.test_readfile_nonnumericarg                               .. ok!


Tests for create_tests.CreatefileTest (6/6 passed)
--

1) create_tests.CreatefileTest.test_duplicatefilename                                 .. ok!
2) create_tests.CreatefileTest.test_emptyfentryatend                                  .. ok!
3) create_tests.CreatefileTest.test_emptyfentryinmiddle                               .. ok!
4) create_tests.CreatefileTest.test_emptyfs                                           .. ok!
5) create_tests.CreatefileTest.test_nametoolong                                       .. ok!
6) create_tests.CreatefileTest.test_nofentry                                          .. ok!


Tests for delete_tests.DeletefileTest (7/7 passed)
--

1) delete_tests.DeletefileTest.test_filenotfound                                      .. ok!
2) delete_tests.DeletefileTest.test_multipledatablock_fentry                          .. ok!
3) delete_tests.DeletefileTest.test_multipledatablock_fnodes                          .. ok!
4) delete_tests.DeletefileTest.test_nodata_fentry                                     .. ok!
5) delete_tests.DeletefileTest.test_nodata_fnodes                                     .. ok!
6) delete_tests.DeletefileTest.test_onedatablock_fentry                               .. ok!
7) delete_tests.DeletefileTest.test_onedatablock_fnodes                               .. ok!


Tests for read_tests.ReadfileTest (7/10 passed)
--

1) read_tests.ReadfileTest.test_blankfentry_before_file                               .. ok!
2) read_tests.ReadfileTest.test_filenotfound                                          .. ok!
3) read_tests.ReadfileTest.test_firstfile_start0_lessthanblocksize                    .. ok!
4) read_tests.ReadfileTest.test_firstfile_start10_morethanblocksize                   .. ok!
5) read_tests.ReadfileTest.test_firstfile_start2_lessthanblocksize                    .. ok!
6) read_tests.ReadfileTest.test_lengthinvalid                                         .. ok!
7) read_tests.ReadfileTest.test_startinvalid                                          .. ok!
8) read_tests.ReadfileTest.test_firstfile_start0_morethanblocksize                    .. error
.. because 'utf-8' codec can't decode byte 0x80 in position 128: invalid start byte (details below):

    Traceback (most recent call last):

      File "/usr/lib/python3.6/unittest/case.py", line 59, in testPartExecutor
        yield

      File "/usr/lib/python3.6/unittest/case.py", line 605, in run
        testMethod()

      File "/res/peters43/209/duxuan1/a2/test_helpers.py", line 158, in _t
        stdout, stderr, returncode = self._run_exec(args=args, input_=input_, timeout=timeout, check=check)

      File "/res/peters43/209/duxuan1/a2/test_helpers.py", line 99, in _run_exec
        **kwargs)

      File "/res/peters43/209/duxuan1/a2/test_helpers.py", line 284, in _exec
        stdout, stderr = proc.communicate(timeout=timeout, input=input_)

      File "/usr/lib/python3.6/subprocess.py", line 863, in communicate
        stdout, stderr = self._communicate(input, endtime, timeout)

      File "/usr/lib/python3.6/subprocess.py", line 1574, in _communicate
        self.stdout.errors)

      File "/usr/lib/python3.6/subprocess.py", line 760, in _translate_newlines
        data = data.decode(encoding, errors)

    UnicodeDecodeError: 'utf-8' codec can't decode byte 0x80 in position 128: invalid start byte


9) read_tests.ReadfileTest.test_firstfile_start3_morethandoubleblocksize              .. error
.. because 'utf-8' codec can't decode byte 0x80 in position 254: invalid start byte (details below):

    Traceback (most recent call last):

      File "/usr/lib/python3.6/unittest/case.py", line 59, in testPartExecutor
        yield

      File "/usr/lib/python3.6/unittest/case.py", line 605, in run
        testMethod()

      File "/res/peters43/209/duxuan1/a2/test_helpers.py", line 158, in _t
        stdout, stderr, returncode = self._run_exec(args=args, input_=input_, timeout=timeout, check=check)

      File "/res/peters43/209/duxuan1/a2/test_helpers.py", line 99, in _run_exec
        **kwargs)

      File "/res/peters43/209/duxuan1/a2/test_helpers.py", line 284, in _exec
        stdout, stderr = proc.communicate(timeout=timeout, input=input_)

      File "/usr/lib/python3.6/subprocess.py", line 863, in communicate
        stdout, stderr = self._communicate(input, endtime, timeout)

      File "/usr/lib/python3.6/subprocess.py", line 1574, in _communicate
        self.stdout.errors)

      File "/usr/lib/python3.6/subprocess.py", line 760, in _translate_newlines
        data = data.decode(encoding, errors)

    UnicodeDecodeError: 'utf-8' codec can't decode byte 0x80 in position 254: invalid start byte


10) read_tests.ReadfileTest.test_middlefile                                            .. error
.. because 'utf-8' codec can't decode byte 0xfe in position 4: invalid start byte (details below):

    Traceback (most recent call last):

      File "/usr/lib/python3.6/unittest/case.py", line 59, in testPartExecutor
        yield

      File "/usr/lib/python3.6/unittest/case.py", line 605, in run
        testMethod()

      File "/res/peters43/209/duxuan1/a2/test_helpers.py", line 158, in _t
        stdout, stderr, returncode = self._run_exec(args=args, input_=input_, timeout=timeout, check=check)

      File "/res/peters43/209/duxuan1/a2/test_helpers.py", line 99, in _run_exec
        **kwargs)

      File "/res/peters43/209/duxuan1/a2/test_helpers.py", line 284, in _exec
        stdout, stderr = proc.communicate(timeout=timeout, input=input_)

      File "/usr/lib/python3.6/subprocess.py", line 863, in communicate
        stdout, stderr = self._communicate(input, endtime, timeout)

      File "/usr/lib/python3.6/subprocess.py", line 1574, in _communicate
        self.stdout.errors)

      File "/usr/lib/python3.6/subprocess.py", line 760, in _translate_newlines
        data = data.decode(encoding, errors)

    UnicodeDecodeError: 'utf-8' codec can't decode byte 0xfe in position 4: invalid start byte




Tests for write_tests.WritefileTest (7/7 passed)
--

1) write_tests.WritefileTest.test_diskfull_largesize                                  .. ok!
2) write_tests.WritefileTest.test_diskfull_size0                                      .. ok!
3) write_tests.WritefileTest.test_filenotfound                                        .. ok!
4) write_tests.WritefileTest.test_largesize_noallocneeded                             .. ok!
5) write_tests.WritefileTest.test_overwriting_lessthanblocksize                       .. ok!
6) write_tests.WritefileTest.test_size0_lessthanblocksize                             .. ok!
7) write_tests.WritefileTest.test_size0_morethanblocksize                             .. ok!


Tests for bad_fs.BadFSTest (0/2 passed)
--

1) bad_fs.BadFSTest.test_badfirstindex                                                .. error
.. because 'utf-8' codec can't decode byte 0xe1 in position 1: invalid continuation byte (details below):

    Traceback (most recent call last):

      File "/usr/lib/python3.6/unittest/case.py", line 59, in testPartExecutor
        yield

      File "/usr/lib/python3.6/unittest/case.py", line 605, in run
        testMethod()

      File "/res/peters43/209/duxuan1/a2/test_helpers.py", line 229, in _t
        stdout, stderr, returncode = self._run_exec(args=args, input_=input_, timeout=timeout, check=check)

      File "/res/peters43/209/duxuan1/a2/test_helpers.py", line 99, in _run_exec
        **kwargs)

      File "/res/peters43/209/duxuan1/a2/test_helpers.py", line 284, in _exec
        stdout, stderr = proc.communicate(timeout=timeout, input=input_)

      File "/usr/lib/python3.6/subprocess.py", line 863, in communicate
        stdout, stderr = self._communicate(input, endtime, timeout)

      File "/usr/lib/python3.6/subprocess.py", line 1574, in _communicate
        self.stdout.errors)

      File "/usr/lib/python3.6/subprocess.py", line 760, in _translate_newlines
        data = data.decode(encoding, errors)

    UnicodeDecodeError: 'utf-8' codec can't decode byte 0xe1 in position 1: invalid continuation byte


2) bad_fs.BadFSTest.test_invalidfname                                                 .. error
.. because 'utf-8' codec can't decode byte 0xb0 in position 2: invalid start byte (details below):

    Traceback (most recent call last):

      File "/usr/lib/python3.6/unittest/case.py", line 59, in testPartExecutor
        yield

      File "/usr/lib/python3.6/unittest/case.py", line 605, in run
        testMethod()

      File "/res/peters43/209/duxuan1/a2/test_helpers.py", line 229, in _t
        stdout, stderr, returncode = self._run_exec(args=args, input_=input_, timeout=timeout, check=check)

      File "/res/peters43/209/duxuan1/a2/test_helpers.py", line 99, in _run_exec
        **kwargs)

      File "/res/peters43/209/duxuan1/a2/test_helpers.py", line 284, in _exec
        stdout, stderr = proc.communicate(timeout=timeout, input=input_)

      File "/usr/lib/python3.6/subprocess.py", line 863, in communicate
        stdout, stderr = self._communicate(input, endtime, timeout)

      File "/usr/lib/python3.6/subprocess.py", line 1574, in _communicate
        self.stdout.errors)

      File "/usr/lib/python3.6/subprocess.py", line 760, in _translate_newlines
        data = data.decode(encoding, errors)

    UnicodeDecodeError: 'utf-8' codec can't decode byte 0xb0 in position 2: invalid start byte




