Autotested Results for A2 submitted by Xuan Du (duxuan1)
Generated at 2020-02-18T20:50:18

Summary of Results: 4 out of 6 tests successfully passed
--

Tests for create_tests.CreatefileTest (2/2 passed)
--

1) create_tests.CreatefileTest.test_emptyfs                                           .. ok!
2) create_tests.CreatefileTest.test_nofentry                                          .. ok!


Tests for read_tests.ReadfileTest (1/2 passed)
--

1) read_tests.ReadfileTest.test_firstfile_start4_morethanblocksize                    .. ok!
2) read_tests.ReadfileTest.test_firstfile_start0_lessthanblocksize                    .. error
.. because 'utf-8' codec can't decode byte 0xfe in position 4: invalid start byte (details below):

    Traceback (most recent call last):

      File "/usr/lib/python3.6/unittest/case.py", line 59, in testPartExecutor
        yield

      File "/usr/lib/python3.6/unittest/case.py", line 605, in run
        testMethod()

      File "/res/peters43/209/duxuan1/a2/test_helpers.py", line 158, in _t
        stdout, stderr, returncode = self._run_exec(args=args, input_=input_, timeout=timeout, check=check)

      File "/res/peters43/209/duxuan1/a2/test_helpers.py", line 99, in _run_exec
        **kwargs)

      File "/res/peters43/209/duxuan1/a2/test_helpers.py", line 284, in _exec
        stdout, stderr = proc.communicate(timeout=timeout, input=input_)

      File "/usr/lib/python3.6/subprocess.py", line 863, in communicate
        stdout, stderr = self._communicate(input, endtime, timeout)

      File "/usr/lib/python3.6/subprocess.py", line 1574, in _communicate
        self.stdout.errors)

      File "/usr/lib/python3.6/subprocess.py", line 760, in _translate_newlines
        data = data.decode(encoding, errors)

    UnicodeDecodeError: 'utf-8' codec can't decode byte 0xfe in position 4: invalid start byte




Tests for write_tests.WritefileTest (1/2 passed)
--

1) write_tests.WritefileTest.test_size0_lessthanblocksize                             .. ok!
2) write_tests.WritefileTest.test_size2_morethanblocksize                             .. failed
.. because False is not true (details below):

    Traceback (most recent call last):

      File "/usr/lib/python3.6/unittest/case.py", line 59, in testPartExecutor
        yield

      File "/usr/lib/python3.6/unittest/case.py", line 605, in run
        testMethod()

      File "/res/peters43/209/duxuan1/a2/test_helpers.py", line 243, in _t
        self.assertTrue(_diff_files(outputname, solname, start, len))

      File "/usr/lib/python3.6/unittest/case.py", line 682, in assertTrue
        raise self.failureException(msg)

    AssertionError: False is not true




